<?xml version="1.0" ?>
<!-- =================================================================================== -->
<!-- |    This document was autogenerated by xacro from /home/ebin/urdf_ws/src/archie_description/urdf/archie.xacro | -->
<!-- |    EDITING THIS FILE BY HAND IS NOT RECOMMENDED                                 | -->
<!-- =================================================================================== -->
<robot name="archie">
    <material name="aluminum">
        <color rgba="0.5 0.5 0.5 1" />
    </material>
    <material name="plastic">
        <color rgba="0.1 0.1 0.1 1" />
    </material>
    <link name="base_footprint" />
    <link name="base_link">
        <inertial>
            <origin rpy="0 0 0" xyz="0.00733453928201211 0.00515194891324405 0.0600590776385257" />
            <mass value="2.31119340602887" />
            <inertia ixx="0.0820365921519234" ixy="0.00145402442171753" ixz="0.00779736449789006" iyy="0.0655678562763293" iyz="0.000717742863308553" izz="0.055720058769593" />
        </inertial>
        <visual>
            <origin rpy="0 0 0" xyz="0 0 0" />
            <geometry>
                <mesh filename="package://archie_description/meshes/base_link.STL" />
            </geometry>
            <material name="">
                <color rgba="0.752941176470588 0.752941176470588 0.752941176470588 1" />
            </material>
        </visual>
        <collision>
            <origin rpy="0 0 0" xyz="0 0 0" />
            <geometry>
                <mesh filename="package://archie_description/meshes/base_link_collision.STL" />
            </geometry>
        </collision>
    </link>
    <joint name="base_joint" type="fixed">
        <origin rpy="-0.00042319083381432 -1.21232042851455E-17 -2.84597815903914E-14" xyz="0 0 0.0549" />
        <parent link="base_footprint" />
        <child link="base_link" />
        <axis xyz="0 0 0" />
    </joint>
    <link name="left_wheel">
        <inertial>
            <origin rpy="0 0 0" xyz="8.53355384062282E-05 -0.00230829105658181 1.03831180030822E-05" />
            <mass value="0.187715234825625" />
            <inertia ixx="0.000202585219170499" ixy="-1.42815369422969E-09" ixz="1.20829539485635E-07" iyy="0.000370271049787534" iyz="-2.23782609806456E-10" izz="0.000201813608090561" />
        </inertial>
        <visual>
            <origin rpy="0 0 0" xyz="0 0 0" />
            <geometry>
                <mesh filename="package://archie_description/meshes/left_wheel.STL" />
            </geometry>
            <material name="">
                <color rgba="0.294117647058824 0.294117647058824 0.294117647058824 1" />
            </material>
        </visual>
    </link>
    <joint name="left_wheel_joint" type="fixed">
        <origin rpy="0.00042319083381432 9.39672386974239E-20 2.84250897059694E-14" xyz="0 0.23 0" />
        <parent link="base_link" />
        <child link="left_wheel" />
        <axis xyz="0 0 0" />
    </joint>
    <link name="right_wheel">
        <inertial>
            <origin rpy="0 0 0" xyz="-8.53355384065613E-05 0.00230829105658387 1.57153402591537E-05" />
            <mass value="0.187715234825624" />
            <inertia ixx="0.000202585219170499" ixy="-1.42815369425293E-09" ixz="-1.20829539485632E-07" iyy="0.000370271049787534" iyz="2.23782609841977E-10" izz="0.00020181360809056" />
        </inertial>
        <visual>
            <origin rpy="0 0 0" xyz="0 0 0" />
            <geometry>
                <mesh filename="package://archie_description/meshes/right_wheel.STL" />
            </geometry>
            <material name="">
                <color rgba="0.294117647058824 0.294117647058824 0.294117647058824 1" />
            </material>
        </visual>
    </link>
    <joint name="right_wheel_joint" type="fixed">
        <origin rpy="0.00042319083381432 -2.68613784773866E-17 9.21205716330717E-14" xyz="0 -0.23 0" />
        <parent link="base_link" />
        <child link="right_wheel" />
        <axis xyz="0 0.99999991045476 -0.00042319082118275" />
    </joint>
    <link name="laser">
        <inertial>
            <origin rpy="0 0 0" xyz="0.0119189312284075 -0.000416345790583944 -0.014770311626675" />
            <mass value="0.0735157407518519" />
            <inertia ixx="2.97357868328591E-05" ixy="-5.26803442400641E-07" ixz="9.41977428915003E-06" iyy="5.97754418539939E-05" iyz="2.66365610700581E-07" izz="6.8272006613991E-05" />
        </inertial>
        <visual>
            <origin rpy="0 0 0" xyz="0 0 0" />
            <geometry>
                <mesh filename="package://archie_description/meshes/lidar.STL" />
            </geometry>
            <material name="">
                <color rgba="0.752941176470588 0.752941176470588 0.752941176470588 1" />
            </material>
        </visual>
    </link>
    <joint name="lidar_joint" type="fixed">
        <origin rpy="-7.92848647505339E-20 0.00042319083381432 -1.57079632679487" xyz="0.219 -1.00719415356276E-05 0.0237999978688232" />
        <parent link="base_link" />
        <child link="laser" />
        <axis xyz="0 0 0" />
    </joint>
    <link name="camera_tilt">
        <inertial>
            <origin rpy="0 0 0" xyz="0.0288618063642319 -5.96959703891287E-11 0.0114042265638415" />
            <mass value="0.0217393031475654" />
            <inertia ixx="2.55450729458819E-05" ixy="1.01285402595985E-15" ixz="-2.45565933576798E-07" iyy="2.56233006846258E-06" iyz="1.078452381831E-14" izz="2.40718051317747E-05" />
        </inertial>
        <visual>
            <origin rpy="0 0 0" xyz="0 0 0" />
            <geometry>
                <mesh filename="package://archie_description/meshes/camera_tilt.STL" />
            </geometry>
            <material name="">
                <color rgba="0.792156862745098 0.819607843137255 0.933333333333333 1" />
            </material>
        </visual>
    </link>
    <joint name="camera_tilt_joint" type="revolute">
        <origin rpy="0.000423190833828544 -2.81011526104924E-16 2.84249707446941E-14" xyz="-0.0430000000000003 -0.000256393181805814 0.60585708860552" />
        <parent link="base_link" />
        <child link="camera_tilt" />
        <axis xyz="0 1 0" />
        <limit effort="1.2" lower="-1.5708" upper="1.52" velocity="5.236" />
    </joint>
    <link name="camera_base" />
    <joint name="camera_base_joint" type="fixed">
        <origin rpy="0 0 0" xyz="0.0432049999999997 0 -0.00250000000000017" />
        <parent link="camera_tilt" />
        <child link="camera_base" />
        <axis xyz="0 0 0" />
    </joint>
    <!-- camera body, with origin at bottom screw mount -->
    <joint name="camera_joint" type="fixed">
        <origin rpy="0 0 0" xyz="0 0 0" />
        <parent link="camera_base" />
        <child link="camera_bottom_screw_frame" />
    </joint>
    <link name="camera_bottom_screw_frame" />
    <joint name="camera_link_joint" type="fixed">
        <origin rpy="0 0 0" xyz="0.011150000000000002 0.0475 0.0145" />
        <parent link="camera_bottom_screw_frame" />
        <child link="camera_link" />
    </joint>
    <link name="camera_link">
        <visual>
            <!-- the mesh origin is at front plate in between the two infrared camera axes -->
            <!-- <origin xyz="${d455_zero_depth_to_glass-d455_cam_depth/2} ${-d455_cam_depth_py} 0" rpy="0 0 0"/> -->
            <origin rpy="1.5707963267948966 0 1.5707963267948966" xyz="0.0046500000000000005 -0.0475 0" />
            <geometry>
                <!-- <box size="${d455_cam_depth} ${d455_cam_width} ${d455_cam_height}"/> -->
                <mesh filename="package://realsense2_description/meshes/d455.stl" scale="0.001 0.001 0.001" />
            </geometry>
            <material name="aluminum" />
        </visual>
        <collision>
            <origin rpy="0 0 0" xyz="-0.00845 -0.0475 0" />
            <geometry>
                <box size="0.026 0.124 0.029" />
            </geometry>
        </collision>
        <inertial>
            <!-- The following are not reliable values, and should not be used for modeling -->
            <mass value="0.072" />
            <origin xyz="0 0 0" rpy="0 0 0" />
            <inertia ixx="0.003881243" ixy="0.0" ixz="0.0" iyy="0.000498940" iyz="0.0" izz="0.003879257" />
        </inertial>
    </link>
    <link name="arm_base" />
    <joint name="arm_base_joint" type="fixed">
        <origin rpy="0.00042319 2.2426E-18 2.3348E-14" xyz="0.20305 -0.10004 0.092958" />
        <parent link="base_link" />
        <child link="arm_base" />
        <axis xyz="0 0 0" />
    </joint>
    <link name="sting_base">
        <inertial>
            <origin rpy="0 0 0" xyz="-0.0306847245973906 0.00297469188423153 0.0179502559896504" />
            <mass value="0.208424947541378" />
            <inertia ixx="0.000170859916484587" ixy="7.66647075115288E-06" ixz="-1.87765482676613E-05" iyy="0.000257551852637342" iyz="2.79158713422585E-07" izz="0.000322531498669573" />
        </inertial>
        <visual>
            <origin rpy="0 0 0" xyz="0 0 0" />
            <geometry>
                <mesh filename="package://sting_description/meshes/base_link.STL" />
            </geometry>
            <material name="">
                <color rgba="0.792156862745098 0.819607843137255 0.933333333333333 1" />
            </material>
        </visual>
        <collision>
            <origin rpy="0 0 0" xyz="0 0 0" />
            <geometry>
                <mesh filename="package://sting_description/meshes/base_link_collision.STL" />
            </geometry>
        </collision>
    </link>
    <joint name="sting_base_joint" type="fixed">
        <origin rpy="0 0 0" xyz="0 0 0" />
        <parent link="arm_base" />
        <child link="sting_base" />
    </joint>
    <link name="shoulder">
        <inertial>
            <origin rpy="0 0 0" xyz="-2.83701451220253E-10 0.000650440813576972 0.0296441737600373" />
            <mass value="0.0886507468374865" />
            <inertia ixx="4.39599938957944E-05" ixy="-4.10056983368094E-13" ixz="-2.26716263020998E-14" iyy="3.64657646135674E-05" iyz="-2.49947341733224E-07" izz="2.31909272995461E-05" />
        </inertial>
        <visual>
            <origin rpy="0 0 0" xyz="0 0 0" />
            <geometry>
                <mesh filename="package://sting_description/meshes/shoulder.STL" />
            </geometry>
            <material name="">
                <color rgba="0.792156862745098 0.819607843137255 0.933333333333333 1" />
            </material>
        </visual>
        <collision>
            <origin rpy="0 0 0" xyz="0 0 0" />
            <geometry>
                <mesh filename="package://sting_description/meshes/shoulder_collision.STL" />
            </geometry>
        </collision>
    </link>
    <joint name="shoulder_lateral" type="revolute">
        <origin rpy="0 0 5.5511E-17" xyz="0 0 0.0586" />
        <parent link="sting_base" />
        <child link="shoulder" />
        <axis xyz="0 0 1" />
        <limit effort="1.5" lower="-2.0944" upper="2.0944" velocity="0.2" />
    </joint>
    <link name="upper_arm">
        <inertial>
            <origin rpy="0 0 0" xyz="0.0059374683190056 0.00025826476222137 0.116477208759359" />
            <mass value="0.0964875205570864" />
            <inertia ixx="0.000293392741763401" ixy="-1.65504722836251E-07" ixz="-2.68030403800667E-05" iyy="0.000296714836558997" iyz="-1.19420368429977E-06" izz="2.64654966840106E-05" />
        </inertial>
        <visual>
            <origin rpy="0 0 0" xyz="0 0 0" />
            <geometry>
                <mesh filename="package://sting_description/meshes/upper_arm.STL" />
            </geometry>
            <material name="">
                <color rgba="0.792156862745098 0.819607843137255 0.933333333333333 1" />
            </material>
        </visual>
        <collision>
            <origin rpy="0 0 0" xyz="0 0 0" />
            <geometry>
                <mesh filename="package://sting_description/meshes/upper_arm_collision.STL" />
            </geometry>
        </collision>
    </link>
    <joint name="sholder_vertical" type="revolute">
        <origin rpy="0 0 -5.5511E-17" xyz="0 0 0.0462" />
        <parent link="shoulder" />
        <child link="upper_arm" />
        <axis xyz="0 1 0" />
        <limit effort="1.5" lower="-1.5708" upper="1.5708" velocity="0.2" />
    </joint>
    <link name="lower_arm_back">
        <inertial>
            <origin rpy="0 0 0" xyz="0.0434959254307221 -1.14636806471113E-09 0.0114920313938176" />
            <mass value="0.0483834887231438" />
            <inertia ixx="1.2677814519069E-05" ixy="-4.44863666688638E-12" ixz="-2.71995442627541E-07" iyy="1.54367273768713E-05" iyz="4.54047154489777E-13" izz="1.06356238691095E-05" />
        </inertial>
        <visual>
            <origin rpy="0 0 0" xyz="0 0 0" />
            <geometry>
                <mesh filename="package://sting_description/meshes/lower_arm_back.STL" />
            </geometry>
            <material name="">
                <color rgba="0.792156862745098 0.819607843137255 0.933333333333333 1" />
            </material>
        </visual>
        <collision>
            <origin rpy="0 0 0" xyz="0 0 0" />
            <geometry>
                <mesh filename="package://sting_description/meshes/lower_arm_back_collision.STL" />
            </geometry>
        </collision>
    </link>
    <joint name="elbow" type="revolute">
        <origin rpy="4.4738E-30 1.0077E-14 3.4001E-16" xyz="0.024 0 0.1644" />
        <parent link="upper_arm" />
        <child link="lower_arm_back" />
        <axis xyz="0 1 0" />
        <limit effort="1.5" lower="-1.5708" upper="1.5708" velocity="0.2" />
    </joint>
    <link name="lower_arm_middle">
        <inertial>
            <origin rpy="0 0 0" xyz="0.214841381906226 0.000357131119188845 0.0845979817439144" />
            <mass value="0.0697643525972458" />
            <inertia ixx="1.21947606720726E-05" ixy="-5.2751996332917E-07" ixz="3.60127078450824E-08" iyy="6.94122378614307E-05" iyz="5.39987996519929E-10" izz="7.13194771252659E-05" />
        </inertial>
        <visual>
            <origin rpy="0 0 0" xyz="0 0 0" />
            <geometry>
                <mesh filename="package://sting_description/meshes/lower_arm_middle.STL" />
            </geometry>
            <material name="">
                <color rgba="0.792156862745098 0.819607843137255 0.933333333333333 1" />
            </material>
        </visual>
        <collision>
            <origin rpy="0 0 0" xyz="0 0 0" />
            <geometry>
                <mesh filename="package://sting_description/meshes/lower_arm_middle_collision.STL" />
            </geometry>
        </collision>
    </link>
    <joint name="lower_arm_yaw" type="revolute">
        <origin rpy="-5.86153888555981E-30 -2.50569359413717E-14 1.41610079671577E-16" xyz="0.062 0 0" />
        /&gt;
        <parent link="lower_arm_back" />
        <child link="lower_arm_middle" />
        <axis xyz="1 0 0" />
        <limit effort="1.5" lower="-3.14159" upper="3.14159" velocity="0.2" />
    </joint>
    <link name="lower_arm_front">
        <inertial>
            <origin rpy="0 0 0" xyz="0.0434959254307224 -1.14636688162972E-09 0.0114920313938176" />
            <mass value="0.0483834887231438" />
            <inertia ixx="1.2677814519069E-05" ixy="-4.44863665996012E-12" ixz="-2.71995442627538E-07" iyy="1.54367273768713E-05" iyz="4.54047171613963E-13" izz="1.06356238691095E-05" />
        </inertial>
        <visual>
            <origin rpy="0 0 0" xyz="0 0 0" />
            <geometry>
                <mesh filename="package://sting_description/meshes/lower_arm_front.STL" />
            </geometry>
            <material name="">
                <color rgba="0.792156862745098 0.819607843137255 0.933333333333333 1" />
            </material>
        </visual>
        <collision>
            <origin rpy="0 0 0" xyz="0 0 0" />
            <geometry>
                <mesh filename="package://sting_description/meshes/lower_arm_front_collision.STL" />
            </geometry>
        </collision>
    </link>
    <joint name="lower_arm_vertical" type="revolute">
        <origin rpy="-2.31296463463572E-15 2.26630175445237E-14 1.94005809150057E-15" xyz="0.0875000000000006 0 0" />
        <parent link="lower_arm_middle" />
        <child link="lower_arm_front" />
        <axis xyz="0 1 0" />
        <limit effort="1.5" lower="-1.5708" upper="1.5708" velocity="0.2" />
    </joint>
    <link name="gripper_frame" />
    <joint name="gripper_yaw" type="revolute">
        <origin rpy="2.31296463463576E-15 -2.26630175445237E-14 -1.94005809150062E-15" xyz="0.0620000000000001 0 0" />
        <parent link="lower_arm_front" />
        <child link="gripper_frame" />
        <axis xyz="1 0 0" />
        <limit effort="1.5" lower="-3.14159" upper="3.14159" velocity="0.2" />
    </joint>
    <link name="gripper">
        <inertial>
            <origin rpy="0 0 0" xyz="0.194704951724816 -2.17324802095215E-08 0.12068685472718" />
            <mass value="0.0886007401728508" />
            <inertia ixx="3.41353282847447E-05" ixy="-6.3636069010898E-11" ixz="7.59006185089717E-07" iyy="5.03382529039198E-05" iyz="2.31748941043985E-11" izz="3.8064016603647E-05" />
        </inertial>
        <visual>
            <origin rpy="0 0 0" xyz="0 0 0" />
            <geometry>
                <mesh filename="package://sting_description/meshes/gripper.STL" />
            </geometry>
            <material name="">
                <color rgba="0.792156862745098 0.819607843137255 0.933333333333333 1" />
            </material>
        </visual>
        <collision>
            <origin rpy="0 0 0" xyz="0 0 0" />
            <geometry>
                <mesh filename="package://sting_description/meshes/gripper_collision.STL" />
            </geometry>
        </collision>
    </link>
    <joint name="gripper_joint" type="fixed">
        <origin rpy="0 0 0" xyz="0 0 0" />
        <parent link="gripper_frame" />
        <child link="gripper" />
    </joint>
    <link name="left_finger">
        <inertial>
            <origin rpy="0 0 0" xyz="0.0208098801732191 0.0499696696707152 0.0100306977135814" />
            <mass value="0.0335122683871604" />
            <inertia ixx="3.47056370294739E-05" ixy="-9.08295917628388E-06" ixz="6.80086286395204E-06" iyy="3.1260293364006E-05" iyz="7.57592794813548E-06" izz="5.35698354765624E-05" />
        </inertial>
        <visual>
            <origin rpy="0 0 0" xyz="0 0 0" />
            <geometry>
                <mesh filename="package://sting_description/meshes/left_finger.STL" />
            </geometry>
            <material name="">
                <color rgba="0.792156862745098 0.819607843137255 0.933333333333333 1" />
            </material>
        </visual>
        <collision>
            <origin rpy="0 0 0" xyz="0 0 0" />
            <geometry>
                <mesh filename="package://sting_description/meshes/left_finger_collision.STL" />
            </geometry>
        </collision>
    </link>
    <joint name="left_finger_joint" type="prismatic">
        <origin rpy="-4.78783679369601E-16 1.52572064754592E-14 -1.41610079671578E-16" xyz="0.0585000000000001 0 0" />
        <parent link="gripper" />
        <child link="left_finger" />
        <axis xyz="0 -1 0" />
        <limit effort="1" lower="0" upper="0.06" velocity="0.2" />
    </joint>
    <link name="right_finger">
        <inertial>
            <origin rpy="0 0 0" xyz="0.02081 -0.04997 -0.010231" />
            <mass value="0.033512" />
            <inertia ixx="3.4706E-05" ixy="9.083E-06" ixz="-6.8009E-06" iyy="3.126E-05" iyz="7.5759E-06" izz="5.357E-05" />
        </inertial>
        <visual>
            <origin rpy="0 0 0" xyz="0 0 0" />
            <geometry>
                <mesh filename="package://sting_description/meshes/right_finger.STL" />
            </geometry>
            <material name="">
                <color rgba="0.79216 0.81961 0.93333 1" />
            </material>
        </visual>
        <collision>
            <origin rpy="0 0 0" xyz="0 0 0" />
            <geometry>
                <mesh filename="package://sting_description/meshes/right_finger_collision.STL" />
            </geometry>
        </collision>
    </link>
    <joint name="right_finger_joint" type="prismatic">
        <origin rpy="-4.78783679369601E-16 1.52572064754592E-14 -1.41610079671578E-16" xyz="0.0585000000000001 0 0" />
        <parent link="gripper" />
        <child link="right_finger" />
        <axis xyz="0 1 0" />
        <mimic joint="left_finger_joint" multiplier="1" />
        <limit effort="1" lower="0" upper="0.06" velocity="0.2" />
    </joint>
    <transmission name="trans_camera_tilt_joint">
        <type>transmission_interface/SimpleTransmission</type>
        <joint name="camera_tilt_joint">
            <hardwareInterface>hardware_interface/EffortJointInterface</hardwareInterface>
        </joint>
        <actuator name="camera_tilt_joint_motor">
            <hardwareInterface>hardware_interface/EffortJointInterface</hardwareInterface>
            <mechanicalReduction>1</mechanicalReduction>
        </actuator>
    </transmission>
    <transmission name="trans_shoulder_lateral">
        <type>transmission_interface/SimpleTransmission</type>
        <joint name="shoulder_lateral">
            <hardwareInterface>hardware_interface/EffortJointInterface</hardwareInterface>
        </joint>
        <actuator name="shoulder_lateral_motor">
            <hardwareInterface>hardware_interface/EffortJointInterface</hardwareInterface>
            <mechanicalReduction>1</mechanicalReduction>
        </actuator>
    </transmission>
    <transmission name="trans_sholder_vertical">
        <type>transmission_interface/SimpleTransmission</type>
        <joint name="sholder_vertical">
            <hardwareInterface>hardware_interface/EffortJointInterface</hardwareInterface>
        </joint>
        <actuator name="sholder_vertical_motor">
            <hardwareInterface>hardware_interface/EffortJointInterface</hardwareInterface>
            <mechanicalReduction>1</mechanicalReduction>
        </actuator>
    </transmission>
    <transmission name="trans_elbow">
        <type>transmission_interface/SimpleTransmission</type>
        <joint name="elbow">
            <hardwareInterface>hardware_interface/EffortJointInterface</hardwareInterface>
        </joint>
        <actuator name="elbow_motor">
            <hardwareInterface>hardware_interface/EffortJointInterface</hardwareInterface>
            <mechanicalReduction>1</mechanicalReduction>
        </actuator>
    </transmission>
    <transmission name="trans_lower_arm_yaw">
        <type>transmission_interface/SimpleTransmission</type>
        <joint name="lower_arm_yaw">
            <hardwareInterface>hardware_interface/EffortJointInterface</hardwareInterface>
        </joint>
        <actuator name="lower_arm_yaw_motor">
            <hardwareInterface>hardware_interface/EffortJointInterface</hardwareInterface>
            <mechanicalReduction>1</mechanicalReduction>
        </actuator>
    </transmission>
    <transmission name="trans_lower_arm_vertical">
        <type>transmission_interface/SimpleTransmission</type>
        <joint name="lower_arm_vertical">
            <hardwareInterface>hardware_interface/EffortJointInterface</hardwareInterface>
        </joint>
        <actuator name="lower_arm_vertical_motor">
            <hardwareInterface>hardware_interface/EffortJointInterface</hardwareInterface>
            <mechanicalReduction>1</mechanicalReduction>
        </actuator>
    </transmission>
    <transmission name="trans_gripper_yaw">
        <type>transmission_interface/SimpleTransmission</type>
        <joint name="gripper_yaw">
            <hardwareInterface>hardware_interface/EffortJointInterface</hardwareInterface>
        </joint>
        <actuator name="gripper_yaw_motor">
            <hardwareInterface>hardware_interface/EffortJointInterface</hardwareInterface>
            <mechanicalReduction>1</mechanicalReduction>
        </actuator>
    </transmission>
    <transmission name="trans_left_finger_joint">
        <type>transmission_interface/SimpleTransmission</type>
        <joint name="left_finger_joint">
            <hardwareInterface>hardware_interface/EffortJointInterface</hardwareInterface>
        </joint>
        <actuator name="left_finger_joint_motor">
            <hardwareInterface>hardware_interface/EffortJointInterface</hardwareInterface>
            <mechanicalReduction>1</mechanicalReduction>
        </actuator>
    </transmission>
    <transmission name="trans_right_finger_joint">
        <type>transmission_interface/SimpleTransmission</type>
        <joint name="right_finger_joint">
            <hardwareInterface>hardware_interface/EffortJointInterface</hardwareInterface>
        </joint>
        <actuator name="right_finger_joint_motor">
            <hardwareInterface>hardware_interface/EffortJointInterface</hardwareInterface>
            <mechanicalReduction>1</mechanicalReduction>
        </actuator>
    </transmission>
    <gazebo>
        <plugin name="gazebo_ros_control">
            <robotNamespace>/</robotNamespace>
        </plugin>
    </gazebo>
</robot>

